<?xml version="1.0"?>
<robot xmlns:xacro="http://www.ros.org/wiki/xacro">

    <!-- Include inertial macros -->
    <xacro:include filename="inertial.xacro" />


    <!-- Wheels Macro -->
    <xacro:macro name="wheel" params="prefix x y x_reflect y_reflect">

        <link name="${prefix}_link">
            <visual>
                <origin xyz="0 0 0" rpy="${pi/2} 0 0" />
                <geometry>
                    <cylinder radius="${wheel_radius}" length="${wheel_width}" />
                </geometry>
                <material name="orange">
                    <color rgba="1.0 0.5 0.0 1.0" />
                </material>                                     
            </visual>

            <collision>
                <origin xyz="0 0 0" rpy="${pi/2} 0 0" />
                <geometry>
                    <cylinder radius="${wheel_radius}" length="${wheel_width}" />
                </geometry>
            </collision>

            <xacro:cyclinder_inertia mass="0.5" radius="${wheel_radius}" height="${wheel_width}" /> 
        </link>

        <joint name="${prefix}_joint" type="continuous">
            <parent link="base_link" />
            <child link="${prefix}_link" />
            <origin
                xyz="${x * x_reflect} ${y * y_reflect} ${-wheel_zoff}"
                rpy="0 0 0" />
            <axis xyz="0 1 0" />
        </joint>

        <gazebo reference="${prefix}_link">
            <material>Gazebo/Orange</material>
            <mu1>1.0</mu1>
            <mu2>1.0</mu2>
            <kp>1000000.0</kp>
            <kd>100.0</kd>
            <minDepth>0.001</minDepth>
            <maxVel>1.0</maxVel>
        </gazebo>

    </xacro:macro>

</robot>